Workbook

Sheet Profit & Loss
A1: Historical teaching fixture | Profit & Loss
A2: USD million · Other units shown in row labels · Blank = unavailable · Reported annual figures
A3: Select a value for its SEC filing; its cell note records the original label, tag, unit and filing date.
A4: Line item | B4: 2021-12-31 | C4: 2022-12-31 | D4: 2023-12-31 | E4: 2024-12-31
A5: Revenues | B5: 800 | C5: 900 | D5: 1000 | E5: 1200
A6: CostOfRevenue | B6: 500 | C6: 550 | D6: 600 | E6: 700
A7: GrossProfit | B7: 300 | C7: 350 | D7: 400 | E7: 500
A8: OperatingIncomeLoss | B8: 80 | C8: 90 | D8: 100 | E8: 180
A9: ProfitLoss | B9: 60 | C9: 70 | D9: 80 | E9: 120
A10: NetIncomeLoss | B10: 58 | C10: 68 | D10: 78 | E10: 118
A11: NetIncomeLossAvailableToCommonStockholdersBasic | B11: 58 | C11: 68 | D11: 78 | E11: 118
A12: InterestExpense | B12: 10 | C12: 10 | D12: 10 | E12: 12
A13: IncomeLossFromContinuingOperationsBeforeIncomeTaxesExtraordinaryItemsNoncontrollingInterest | B13: 75 | C13: 87.5 | D13: 100 | E13: 150
A14: IncomeTaxExpenseBenefit | B14: 15 | C14: 17.5 | D14: 20 | E14: 30
A15: CommonStockDividendsPerShareDeclared (USD/shares) | B15: 0.1 | C15: 0.12 | D15: 0.15 | E15: 0.25
A16: EarningsPerShareBasic (USD/shares) | B16: 0.58 | C16: 0.68 | D16: 0.78 | E16: 1.475
... A18: WeightedAverageNumberOfDilutedSharesOutstanding (shares) | B18: 100000000 | C18: 100000000 | D18: 100000000 | E18: 80000000

Sheet Balance Sheet
A1: Historical teaching fixture | Balance Sheet
A2: USD million · Other units shown in row labels · Blank = unavailable · Reported annual figures
A3: Select a value for its SEC filing; its cell note records the original label, tag, unit and filing date.
A4: Line item | B4: 2021-12-31 | C4: 2022-12-31 | D4: 2023-12-31 | E4: 2024-12-31
A5: Assets | B5: 800 | C5: 900 | D5: 1100 | E5: 1300
A6: LiabilitiesAndStockholdersEquity | B6: 800 | C6: 900 | D6: 1100 | E6: 1300
A7: AssetsCurrent | B7: 250 | C7: 300 | D7: 350 | E7: 400
A8: LiabilitiesCurrent | B8: 100 | C8: 120 | D8: 140 | E8: 160
A9: CashAndCashEquivalentsAtCarryingValue | B9: 40 | C9: 45 | D9: 50 | E9: 60
A10: ShortTermInvestments | B10: 10 | C10: 12 | D10: 15 | E10: 20
A11: AccountsReceivableNetCurrent | B11: 70 | C11: 80 | D11: 90 | E11: 110
A12: InventoryNet | B12: 100 | C12: 110 | D12: 120 | E12: 160
A13: AccountsPayableCurrent | B13: 50 | C13: 60 | D13: 70 | E13: 90
A14: CommonStockholdersEquity | B14: 400 | C14: 450 | D14: 500 | E14: 600
A15: DebtAndCapitalLeaseObligations | B15: 100 | C15: 120 | D15: 150 | E15: 180
A16: StockholdersEquityIncludingPortionAttributableToNoncontrollingInterest | B16: 410 | C16: 460 | D16: 510 | E16: 620

Sheet Cash Flow
A1: Historical teaching fixture | Cash Flow
A2: USD million · Other units shown in row labels · Blank = unavailable · Reported annual figures
A3: Cash Flow Detail contains every reported cash-flow row. Values here are reported totals, not calculated estimates.
A4: Line item | B4: 2021-12-31 | C4: 2022-12-31 | D4: 2023-12-31 | E4: 2024-12-31
A5: NetCashProvidedByUsedInOperatingActivities | B5: 90 | C5: 100 | D5: 110 | E5: 150

Sheet Cash Flow Detail
A1: Historical teaching fixture | Cash Flow Detail
A2: USD million · Other units shown in row labels · Blank = unavailable · Reported annual figures
A3: Select a value for its SEC filing; its cell note records the original label, tag, unit and filing date.
A4: Line item | B4: 2021-12-31 | C4: 2022-12-31 | D4: 2023-12-31 | E4: 2024-12-31
A5: NetCashProvidedByUsedInOperatingActivities | B5: 90 | C5: 100 | D5: 110 | E5: 150
A6: PaymentsToAcquirePropertyPlantAndEquipment | B6: 30 | C6: 40 | D6: 45 | E6: 50
A7: DepreciationDepletionAndAmortization | B7: 20 | C7: 22 | D7: 25 | E7: 30
A8: PaymentsOfDividendsCommonStock | B8: 10 | C8: 12 | D8: 15 | E8: 20
A9: PaymentsForRepurchaseOfCommonStock | B9: 20 | C9: 25 | D9: 30 | E9: 40

Sheet Data Sheet
A1: Historical teaching fixture | Data Sheet
A2: Latest 20 fiscal periods maximum · USD million · Other units shown in row labels · Blank = unavailable · Reported annual figures
A3: Selected annual statements in one matrix. Select a value for its SEC source and cell note. Full original records: Source Data.
A4: Profit & Loss
A5: Reported line item | B5: 2021-12-31 | C5: 2022-12-31 | D5: 2023-12-31 | E5: 2024-12-31
A6: Revenues | B6: 800 | C6: 900 | D6: 1000 | E6: 1200
A7: CostOfRevenue | B7: 500 | C7: 550 | D7: 600 | E7: 700
A8: GrossProfit | B8: 300 | C8: 350 | D8: 400 | E8: 500
A9: OperatingIncomeLoss | B9: 80 | C9: 90 | D9: 100 | E9: 180
A10: ProfitLoss | B10: 60 | C10: 70 | D10: 80 | E10: 120
A11: NetIncomeLoss | B11: 58 | C11: 68 | D11: 78 | E11: 118
A12: NetIncomeLossAvailableToCommonStockholdersBasic | B12: 58 | C12: 68 | D12: 78 | E12: 118
A13: InterestExpense | B13: 10 | C13: 10 | D13: 10 | E13: 12
A14: IncomeLossFromContinuingOperationsBeforeIncomeTaxesExtraordinaryItemsNoncontrollingInterest | B14: 75 | C14: 87.5 | D14: 100 | E14: 150
A15: IncomeTaxExpenseBenefit | B15: 15 | C15: 17.5 | D15: 20 | E15: 30
A16: CommonStockDividendsPerShareDeclared (USD/shares) | B16: 0.1 | C16: 0.12 | D16: 0.15 | E16: 0.25
A17: EarningsPerShareBasic (USD/shares) | B17: 0.58 | C17: 0.68 | D17: 0.78 | E17: 1.475
... A19: WeightedAverageNumberOfDilutedSharesOutstanding (shares) | B19: 100000000 | C19: 100000000 | D19: 100000000 | E19: 80000000
A21: Balance Sheet
A22: Reported line item | B22: 2021-12-31 | C22: 2022-12-31 | D22: 2023-12-31 | E22: 2024-12-31
A23: Assets | B23: 800 | C23: 900 | D23: 1100 | E23: 1300
A24: LiabilitiesAndStockholdersEquity | B24: 800 | C24: 900 | D24: 1100 | E24: 1300
A25: AssetsCurrent | B25: 250 | C25: 300 | D25: 350 | E25: 400
A26: LiabilitiesCurrent | B26: 100 | C26: 120 | D26: 140 | E26: 160
A27: CashAndCashEquivalentsAtCarryingValue | B27: 40 | C27: 45 | D27: 50 | E27: 60
A28: ShortTermInvestments | B28: 10 | C28: 12 | D28: 15 | E28: 20
A29: AccountsReceivableNetCurrent | B29: 70 | C29: 80 | D29: 90 | E29: 110
A30: InventoryNet | B30: 100 | C30: 110 | D30: 120 | E30: 160
A31: AccountsPayableCurrent | B31: 50 | C31: 60 | D31: 70 | E31: 90
A32: CommonStockholdersEquity | B32: 400 | C32: 450 | D32: 500 | E32: 600
A33: DebtAndCapitalLeaseObligations | B33: 100 | C33: 120 | D33: 150 | E33: 180
A34: StockholdersEquityIncludingPortionAttributableToNoncontrollingInterest | B34: 410 | C34: 460 | D34: 510 | E34: 620
A36: Cash Flow
A37: Reported line item | B37: 2021-12-31 | C37: 2022-12-31 | D37: 2023-12-31 | E37: 2024-12-31
A38: NetCashProvidedByUsedInOperatingActivities | B38: 90 | C38: 100 | D38: 110 | E38: 150
A39: PaymentsToAcquirePropertyPlantAndEquipment | B39: 30 | C39: 40 | D39: 45 | E39: 50
A40: DepreciationDepletionAndAmortization | B40: 20 | C40: 22 | D40: 25 | E40: 30
A41: PaymentsOfDividendsCommonStock | B41: 10 | C41: 12 | D41: 15 | E41: 20
A42: PaymentsForRepurchaseOfCommonStock | B42: 20 | C42: 25 | D42: 30 | E42: 40

Sheet Source Data
A1: Historical teaching fixture | Source Data
A2: Raw source values and optional statement presentation values retain their reported units. Original instant contexts are separate from annual display periods. No monetary scaling or currency conversion is applied on this sheet.
A4: Statement | B4: SEC tag / row identifier | C4: Reported label | D4: Reported unit | E4: Source/XBRL value (unscaled) | F4: Annual display period start | G4: Annual display period end | H4: Accession | I4: Filed | J4: Form | K4: Extraction | L4: Selection reason | M4: Source filing | N4: Displayed cells | O4: Statement presentation value (unscaled) | P4: Original source instant | Q4: Row role | R4: Reported section | S4: Context | T4: Dimensions | U4: Decimals
A5: Profit & Loss | B5: us-gaap:Revenues | C5: Revenues | D5: USD | E5: 800000000 | F5: 2021-01-01 | G5: 2021-12-31 | H5: 0000000001-21-000001 | I5: 2022-02-01 | J5: 10-K | K5: companyfacts | M5: https://www.sec.gov/Archives/edgar/data/1/000000000121000001/annual.htm | N5: 'Profit & Loss'!B5; 'Data Sheet'!B6 | U5: -3
A6: Profit & Loss | B6: us-gaap:Revenues | C6: Revenues | D6: USD | E6: 900000000 | F6: 2022-01-01 | G6: 2022-12-31 | H6: 0000000001-22-000001 | I6: 2023-02-01 | J6: 10-K | K6: companyfacts | M6: https://www.sec.gov/Archives/edgar/data/1/000000000122000001/annual.htm | N6: 'Profit & Loss'!C5; 'Data Sheet'!C6 | U6: -3
A7: Profit & Loss | B7: us-gaap:Revenues | C7: Revenues | D7: USD | E7: 1000000000 | F7: 2023-01-01 | G7: 2023-12-31 | H7: 0000000001-23-000001 | I7: 2024-02-01 | J7: 10-K | K7: companyfacts | M7: https://www.sec.gov/Archives/edgar/data/1/000000000123000001/annual.htm | N7: 'Profit & Loss'!D5; 'Data Sheet'!D6 | U7: -3
A8: Profit & Loss | B8: us-gaap:Revenues | C8: Revenues | D8: USD | E8: 1200000000 | F8: 2024-01-01 | G8: 2024-12-31 | H8: 0000000001-24-000001 | I8: 2025-02-01 | J8: 10-K | K8: companyfacts | M8: https://www.sec.gov/Archives/edgar/data/1/000000000124000001/annual.htm | N8: 'Profit & Loss'!E5; 'Data Sheet'!E6 | U8: -3
A9: Profit & Loss | B9: us-gaap:CostOfRevenue | C9: CostOfRevenue | D9: USD | E9: 500000000 | F9: 2021-01-01 | G9: 2021-12-31 | H9: 0000000001-21-000001 | I9: 2022-02-01 | J9: 10-K | K9: companyfacts | M9: https://www.sec.gov/Archives/edgar/data/1/000000000121000001/annual.htm | N9: 'Profit & Loss'!B6; 'Data Sheet'!B7 | U9: -3
A10: Profit & Loss | B10: us-gaap:CostOfRevenue | C10: CostOfRevenue | D10: USD | E10: 550000000 | F10: 2022-01-01 | G10: 2022-12-31 | H10: 0000000001-22-000001 | I10: 2023-02-01 | J10: 10-K | K10: companyfacts | M10: https://www.sec.gov/Archives/edgar/data/1/000000000122000001/annual.htm | N10: 'Profit & Loss'!C6; 'Data Sheet'!C7 | U10: -3
A11: Profit & Loss | B11: us-gaap:CostOfRevenue | C11: CostOfRevenue | D11: USD | E11: 600000000 | F11: 2023-01-01 | G11: 2023-12-31 | H11: 0000000001-23-000001 | I11: 2024-02-01 | J11: 10-K | K11: companyfacts | M11: https://www.sec.gov/Archives/edgar/data/1/000000000123000001/annual.htm | N11: 'Profit & Loss'!D6; 'Data Sheet'!D7 | U11: -3
A12: Profit & Loss | B12: us-gaap:CostOfRevenue | C12: CostOfRevenue | D12: USD | E12: 700000000 | F12: 2024-01-01 | G12: 2024-12-31 | H12: 0000000001-24-000001 | I12: 2025-02-01 | J12: 10-K | K12: companyfacts | M12: https://www.sec.gov/Archives/edgar/data/1/000000000124000001/annual.htm | N12: 'Profit & Loss'!E6; 'Data Sheet'!E7 | U12: -3
A13: Profit & Loss | B13: us-gaap:GrossProfit | C13: GrossProfit | D13: USD | E13: 300000000 | F13: 2021-01-01 | G13: 2021-12-31 | H13: 0000000001-21-000001 | I13: 2022-02-01 | J13: 10-K | K13: companyfacts | M13: https://www.sec.gov/Archives/edgar/data/1/000000000121000001/annual.htm | N13: 'Profit & Loss'!B7; 'Data Sheet'!B8 | U13: -3
A14: Profit & Loss | B14: us-gaap:GrossProfit | C14: GrossProfit | D14: USD | E14: 350000000 | F14: 2022-01-01 | G14: 2022-12-31 | H14: 0000000001-22-000001 | I14: 2023-02-01 | J14: 10-K | K14: companyfacts | M14: https://www.sec.gov/Archives/edgar/data/1/000000000122000001/annual.htm | N14: 'Profit & Loss'!C7; 'Data Sheet'!C8 | U14: -3
A15: Profit & Loss | B15: us-gaap:GrossProfit | C15: GrossProfit | D15: USD | E15: 400000000 | F15: 2023-01-01 | G15: 2023-12-31 | H15: 0000000001-23-000001 | I15: 2024-02-01 | J15: 10-K | K15: companyfacts | M15: https://www.sec.gov/Archives/edgar/data/1/000000000123000001/annual.htm | N15: 'Profit & Loss'!D7; 'Data Sheet'!D8 | U15: -3
A16: Profit & Loss | B16: us-gaap:GrossProfit | C16: GrossProfit | D16: USD | E16: 500000000 | F16: 2024-01-01 | G16: 2024-12-31 | H16: 0000000001-24-000001 | I16: 2025-02-01 | J16: 10-K | K16: companyfacts | M16: https://www.sec.gov/Archives/edgar/data/1/000000000124000001/annual.htm | N16: 'Profit & Loss'!E7; 'Data Sheet'!E8 | U16: -3
... A36: Profit & Loss | B36: us-gaap:InterestExpense | C36: InterestExpense | D36: USD | E36: 12000000 | F36: 2024-01-01 | G36: 2024-12-31 | H36: 0000000001-24-000001 | I36: 2025-02-01 | J36: 10-K | K36: companyfacts | M36: https://www.sec.gov/Archives/edgar/data/1/000000000124000001/annual.htm | N36: 'Profit & Loss'!E12; 'Data Sheet'!E13 | U36: -3
A37: Balance Sheet | B37: us-gaap:Assets | C37: Assets | D37: USD | E37: 800000000 | G37: 2021-12-31 | H37: 0000000001-21-000001 | I37: 2022-02-01 | J37: 10-K | K37: companyfacts | M37: https://www.sec.gov/Archives/edgar/data/1/000000000121000001/annual.htm | N37: 'Balance Sheet'!B5; 'Data Sheet'!B23 | U37: -3
A38: Balance Sheet | B38: us-gaap:Assets | C38: Assets | D38: USD | E38: 900000000 | G38: 2022-12-31 | H38: 0000000001-22-000001 | I38: 2023-02-01 | J38: 10-K | K38: companyfacts | M38: https://www.sec.gov/Archives/edgar/data/1/000000000122000001/annual.htm | N38: 'Balance Sheet'!C5; 'Data Sheet'!C23 | U38: -3
A39: Balance Sheet | B39: us-gaap:Assets | C39: Assets | D39: USD | E39: 1100000000 | G39: 2023-12-31 | H39: 0000000001-23-000001 | I39: 2024-02-01 | J39: 10-K | K39: companyfacts | M39: https://www.sec.gov/Archives/edgar/data/1/000000000123000001/annual.htm | N39: 'Balance Sheet'!D5; 'Data Sheet'!D23 | U39: -3
A40: Balance Sheet | B40: us-gaap:Assets | C40: Assets | D40: USD | E40: 1300000000 | G40: 2024-12-31 | H40: 0000000001-24-000001 | I40: 2025-02-01 | J40: 10-K | K40: companyfacts | M40: https://www.sec.gov/Archives/edgar/data/1/000000000124000001/annual.htm | N40: 'Balance Sheet'!E5; 'Data Sheet'!E23 | U40: -3
A41: Balance Sheet | B41: us-gaap:LiabilitiesAndStockholdersEquity | C41: LiabilitiesAndStockholdersEquity | D41: USD | E41: 800000000 | G41: 2021-12-31 | H41: 0000000001-21-000001 | I41: 2022-02-01 | J41: 10-K | K41: companyfacts | M41: https://www.sec.gov/Archives/edgar/data/1/000000000121000001/annual.htm | N41: 'Balance Sheet'!B6; 'Data Sheet'!B24 | U41: -3
A42: Balance Sheet | B42: us-gaap:LiabilitiesAndStockholdersEquity | C42: LiabilitiesAndStockholdersEquity | D42: USD | E42: 900000000 | G42: 2022-12-31 | H42: 0000000001-22-000001 | I42: 2023-02-01 | J42: 10-K | K42: companyfacts | M42: https://www.sec.gov/Archives/edgar/data/1/000000000122000001/annual.htm | N42: 'Balance Sheet'!C6; 'Data Sheet'!C24 | U42: -3
A43: Balance Sheet | B43: us-gaap:LiabilitiesAndStockholdersEquity | C43: LiabilitiesAndStockholdersEquity | D43: USD | E43: 1100000000 | G43: 2023-12-31 | H43: 0000000001-23-000001 | I43: 2024-02-01 | J43: 10-K | K43: companyfacts | M43: https://www.sec.gov/Archives/edgar/data/1/000000000123000001/annual.htm | N43: 'Balance Sheet'!D6; 'Data Sheet'!D24 | U43: -3
A44: Balance Sheet | B44: us-gaap:LiabilitiesAndStockholdersEquity | C44: LiabilitiesAndStockholdersEquity | D44: USD | E44: 1300000000 | G44: 2024-12-31 | H44: 0000000001-24-000001 | I44: 2025-02-01 | J44: 10-K | K44: companyfacts | M44: https://www.sec.gov/Archives/edgar/data/1/000000000124000001/annual.htm | N44: 'Balance Sheet'!E6; 'Data Sheet'!E24 | U44: -3
A45: Balance Sheet | B45: us-gaap:AssetsCurrent | C45: AssetsCurrent | D45: USD | E45: 250000000 | G45: 2021-12-31 | H45: 0000000001-21-000001 | I45: 2022-02-01 | J45: 10-K | K45: companyfacts | M45: https://www.sec.gov/Archives/edgar/data/1/000000000121000001/annual.htm | N45: 'Balance Sheet'!B7; 'Data Sheet'!B25 | U45: -3
A46: Balance Sheet | B46: us-gaap:AssetsCurrent | C46: AssetsCurrent | D46: USD | E46: 300000000 | G46: 2022-12-31 | H46: 0000000001-22-000001 | I46: 2023-02-01 | J46: 10-K | K46: companyfacts | M46: https://www.sec.gov/Archives/edgar/data/1/000000000122000001/annual.htm | N46: 'Balance Sheet'!C7; 'Data Sheet'!C25 | U46: -3
A47: Balance Sheet | B47: us-gaap:AssetsCurrent | C47: AssetsCurrent | D47: USD | E47: 350000000 | G47: 2023-12-31 | H47: 0000000001-23-000001 | I47: 2024-02-01 | J47: 10-K | K47: companyfacts | M47: https://www.sec.gov/Archives/edgar/data/1/000000000123000001/annual.htm | N47: 'Balance Sheet'!D7; 'Data Sheet'!D25 | U47: -3
A48: Balance Sheet | B48: us-gaap:AssetsCurrent | C48: AssetsCurrent | D48: USD | E48: 400000000 | G48: 2024-12-31 | H48: 0000000001-24-000001 | I48: 2025-02-01 | J48: 10-K | K48: companyfacts | M48: https://www.sec.gov/Archives/edgar/data/1/000000000124000001/annual.htm | N48: 'Balance Sheet'!E7; 'Data Sheet'!E25 | U48: -3
... A80: Balance Sheet | B80: us-gaap:DebtAndCapitalLeaseObligations | C80: DebtAndCapitalLeaseObligations | D80: USD | E80: 180000000 | G80: 2024-12-31 | H80: 0000000001-24-000001 | I80: 2025-02-01 | J80: 10-K | K80: companyfacts | M80: https://www.sec.gov/Archives/edgar/data/1/000000000124000001/annual.htm | N80: 'Balance Sheet'!E15; 'Data Sheet'!E33 | U80: -3
A81: Cash Flow | B81: us-gaap:NetCashProvidedByUsedInOperatingActivities | C81: NetCashProvidedByUsedInOperatingActivities | D81: USD | E81: 90000000 | F81: 2021-01-01 | G81: 2021-12-31 | H81: 0000000001-21-000001 | I81: 2022-02-01 | J81: 10-K | K81: companyfacts | M81: https://www.sec.gov/Archives/edgar/data/1/000000000121000001/annual.htm | N81: 'Cash Flow'!B5; 'Cash Flow Detail'!B5; 'Data Sheet'!B38 | U81: -3
A82: Cash Flow | B82: us-gaap:NetCashProvidedByUsedInOperatingActivities | C82: NetCashProvidedByUsedInOperatingActivities | D82: USD | E82: 100000000 | F82: 2022-01-01 | G82: 2022-12-31 | H82: 0000000001-22-000001 | I82: 2023-02-01 | J82: 10-K | K82: companyfacts | M82: https://www.sec.gov/Archives/edgar/data/1/000000000122000001/annual.htm | N82: 'Cash Flow'!C5; 'Cash Flow Detail'!C5; 'Data Sheet'!C38 | U82: -3
A83: Cash Flow | B83: us-gaap:NetCashProvidedByUsedInOperatingActivities | C83: NetCashProvidedByUsedInOperatingActivities | D83: USD | E83: 110000000 | F83: 2023-01-01 | G83: 2023-12-31 | H83: 0000000001-23-000001 | I83: 2024-02-01 | J83: 10-K | K83: companyfacts | M83: https://www.sec.gov/Archives/edgar/data/1/000000000123000001/annual.htm | N83: 'Cash Flow'!D5; 'Cash Flow Detail'!D5; 'Data Sheet'!D38 | U83: -3
A84: Cash Flow | B84: us-gaap:NetCashProvidedByUsedInOperatingActivities | C84: NetCashProvidedByUsedInOperatingActivities | D84: USD | E84: 150000000 | F84: 2024-01-01 | G84: 2024-12-31 | H84: 0000000001-24-000001 | I84: 2025-02-01 | J84: 10-K | K84: companyfacts | M84: https://www.sec.gov/Archives/edgar/data/1/000000000124000001/annual.htm | N84: 'Cash Flow'!E5; 'Cash Flow Detail'!E5; 'Data Sheet'!E38 | U84: -3
A85: Cash Flow | B85: us-gaap:PaymentsToAcquirePropertyPlantAndEquipment | C85: PaymentsToAcquirePropertyPlantAndEquipment | D85: USD | E85: 30000000 | F85: 2021-01-01 | G85: 2021-12-31 | H85: 0000000001-21-000001 | I85: 2022-02-01 | J85: 10-K | K85: companyfacts | M85: https://www.sec.gov/Archives/edgar/data/1/000000000121000001/annual.htm | N85: 'Cash Flow Detail'!B6; 'Data Sheet'!B39 | U85: -3
A86: Cash Flow | B86: us-gaap:PaymentsToAcquirePropertyPlantAndEquipment | C86: PaymentsToAcquirePropertyPlantAndEquipment | D86: USD | E86: 40000000 | F86: 2022-01-01 | G86: 2022-12-31 | H86: 0000000001-22-000001 | I86: 2023-02-01 | J86: 10-K | K86: companyfacts | M86: https://www.sec.gov/Archives/edgar/data/1/000000000122000001/annual.htm | N86: 'Cash Flow Detail'!C6; 'Data Sheet'!C39 | U86: -3
A87: Cash Flow | B87: us-gaap:PaymentsToAcquirePropertyPlantAndEquipment | C87: PaymentsToAcquirePropertyPlantAndEquipment | D87: USD | E87: 45000000 | F87: 2023-01-01 | G87: 2023-12-31 | H87: 0000000001-23-000001 | I87: 2024-02-01 | J87: 10-K | K87: companyfacts | M87: https://www.sec.gov/Archives/edgar/data/1/000000000123000001/annual.htm | N87: 'Cash Flow Detail'!D6; 'Data Sheet'!D39 | U87: -3
A88: Cash Flow | B88: us-gaap:PaymentsToAcquirePropertyPlantAndEquipment | C88: PaymentsToAcquirePropertyPlantAndEquipment | D88: USD | E88: 50000000 | F88: 2024-01-01 | G88: 2024-12-31 | H88: 0000000001-24-000001 | I88: 2025-02-01 | J88: 10-K | K88: companyfacts | M88: https://www.sec.gov/Archives/edgar/data/1/000000000124000001/annual.htm | N88: 'Cash Flow Detail'!E6; 'Data Sheet'!E39 | U88: -3
A89: Profit & Loss | B89: us-gaap:IncomeLossFromContinuingOperationsBeforeIncomeTaxesExtraordinaryItemsNoncontrollingInterest | C89: IncomeLossFromContinuingOperationsBeforeIncomeTaxesExtraordinaryItemsNoncontrollingInterest | D89: USD | E89: 75000000 | F89: 2021-01-01 | G89: 2021-12-31 | H89: 0000000001-21-000001 | I89: 2022-02-01 | J89: 10-K | K89: companyfacts | M89: https://www.sec.gov/Archives/edgar/data/1/000000000121000001/annual.htm | N89: 'Profit & Loss'!B13; 'Data Sheet'!B14 | U89: -3
A90: Profit & Loss | B90: us-gaap:IncomeLossFromContinuingOperationsBeforeIncomeTaxesExtraordinaryItemsNoncontrollingInterest | C90: IncomeLossFromContinuingOperationsBeforeIncomeTaxesExtraordinaryItemsNoncontrollingInterest | D90: USD | E90: 87500000 | F90: 2022-01-01 | G90: 2022-12-31 | H90: 0000000001-22-000001 | I90: 2023-02-01 | J90: 10-K | K90: companyfacts | M90: https://www.sec.gov/Archives/edgar/data/1/000000000122000001/annual.htm | N90: 'Profit & Loss'!C13; 'Data Sheet'!C14 | U90: -3
A91: Profit & Loss | B91: us-gaap:IncomeLossFromContinuingOperationsBeforeIncomeTaxesExtraordinaryItemsNoncontrollingInterest | C91: IncomeLossFromContinuingOperationsBeforeIncomeTaxesExtraordinaryItemsNoncontrollingInterest | D91: USD | E91: 100000000 | F91: 2023-01-01 | G91: 2023-12-31 | H91: 0000000001-23-000001 | I91: 2024-02-01 | J91: 10-K | K91: companyfacts | M91: https://www.sec.gov/Archives/edgar/data/1/000000000123000001/annual.htm | N91: 'Profit & Loss'!D13; 'Data Sheet'!D14 | U91: -3
...

Sheet Sources & Coverage
A1: Historical teaching fixture | Sources & Coverage
A2: 4 selected annual period ends (20 maximum) | 159 raw facts | 0 discovered filings | 0 extraction coverage records
A4: Record | B4: Accession | C4: Form | D4: Report end | E4: Filed | F4: Status | G4: Detail | H4: Source filing
A5: Presentation policy | F5: Latest 20 fiscal periods | G5: Statement tabs and Data Sheet use the same selected financial facts and a maximum of 20 fiscal periods. Source Data retains all supplied raw observations, including older and unselected facts; those are not additional presented periods.

Sheet Read Me
A1: Historical teaching fixture | Read Me
A2: Fishtorian · Historical financial research. Reported facts, transparent calculations, traceable sources.
A4: Topic | B4: Explanation
A5: Company | B5: Historical teaching fixture
A6: Ticker | B6: HIST
A7: SEC CIK | B7: 0000000001
A8: Generated (UTC) | B8: 2026-10-08T03:43:33.903333+00:00
A9: Annual history | B9: Presentation is limited to the latest 20 selected fiscal periods, in chronological order. Statement tabs and Data Sheet retain the same selected columns, including entirely unavailable periods and internal gaps as blanks, matching the online presentation. Sources & Coverage lists unavailable statement periods. Raw observations outside the presentation window may remain in Source Data. Available data does not prove complete lifetime coverage.
A10: Presentation | B10: The main statements use annual columns, section headings and bold reported totals. Cash Flow presents reported cash reconciliation totals; Cash Flow Detail retains every selected company cash-flow line. Data Sheet combines Profit & Loss, Balance Sheet and full Cash Flow in a clean annual matrix using the same selected facts, units and signs. No forecasts, valuations or synthetic totals are added.
A11: Units | B11: Pure currency amounts display in millions of their own reported currency. Shares, currency per share, ratios and all other units are unscaled. The statement note specifies a single reported currency; mixed currencies and other units are identified in row labels. Each cell comment records its exact reported and display unit. No currency conversion occurs.
A12: Data Sheet columns | B12: Column A: reported line item, with units where needed. Columns B through at most U: selected annual fiscal period ends, oldest to newest, repeated for each statement block. Source tags, dates, accessions and links stay in value-cell comments and the separate Source Data audit table.
A13: Raw values | B13: Source Data stores every supplied raw fact and every selected statement fact, unscaled. Displayed cells identifies every statement or Data Sheet cell using each selected fact.
A14: Presentation signs | B14: Where the filing's visible statement sign is available, statement tabs and Data Sheet use that presentation value. For example, an XBRL payments concept can be positive while its cash-flow line is shown negative. Source Data keeps the underlying Source/XBRL value and optional Statement presentation value separately, both unscaled.
A15: Cash-flow reconciliation | B15: Beginning and ending cash can use the same original SEC concept with different instant dates. They remain separate reported rows, identified by cash_begin/cash_end row roles. Annual display period columns identify the verified year being reconciled; Original source instant preserves each actual XBRL context date. These display periods do not turn cash balances into duration facts.
... A30: Withheld inconsistent cells | B30: 0

Sheet Calculation Inputs
A1: Historical teaching fixture | Calculation Inputs
A2: Unscaled calculation graph · source facts and intermediate formulas
A4: ID | B4: Description | C4: Period | D4: Unit | E4: Value / formula | F4: Status | G4: Explanation | H4: Source tag | I4: Original label | J4: Accession | K4: Filed | L4: Source URL | M4: Context | N4: Dimensions | O4: Source decimals
A5: I1 | B5: Revenues | C5: 2021-12-31 | D5: USD | E5: 800000000 | F5: available | H5: us-gaap:Revenues | I5: Revenues | J5: 0000000001-21-000001 | K5: 2022-02-01 | L5: https://www.sec.gov/Archives/edgar/data/1/000000000121000001/annual.htm | O5: -3
A6: I2 | B6: Revenues | C6: 2022-12-31 | D6: USD | E6: 900000000 | F6: available | H6: us-gaap:Revenues | I6: Revenues | J6: 0000000001-22-000001 | K6: 2023-02-01 | L6: https://www.sec.gov/Archives/edgar/data/1/000000000122000001/annual.htm | O6: -3
A7: I3 | B7: Revenues | C7: 2023-12-31 | D7: USD | E7: 1000000000 | F7: available | H7: us-gaap:Revenues | I7: Revenues | J7: 0000000001-23-000001 | K7: 2024-02-01 | L7: https://www.sec.gov/Archives/edgar/data/1/000000000123000001/annual.htm | O7: -3
A8: I4 | B8: Revenues | C8: 2024-12-31 | D8: USD | E8: 1200000000 | F8: available | H8: us-gaap:Revenues | I8: Revenues | J8: 0000000001-24-000001 | K8: 2025-02-01 | L8: https://www.sec.gov/Archives/edgar/data/1/000000000124000001/annual.htm | O8: -3
A9: I5 | B9: GrossProfit | C9: 2021-12-31 | D9: USD | E9: 300000000 | F9: available | H9: us-gaap:GrossProfit | I9: GrossProfit | J9: 0000000001-21-000001 | K9: 2022-02-01 | L9: https://www.sec.gov/Archives/edgar/data/1/000000000121000001/annual.htm | O9: -3
A10: I6 | B10: GrossProfit | C10: 2022-12-31 | D10: USD | E10: 350000000 | F10: available | H10: us-gaap:GrossProfit | I10: GrossProfit | J10: 0000000001-22-000001 | K10: 2023-02-01 | L10: https://www.sec.gov/Archives/edgar/data/1/000000000122000001/annual.htm | O10: -3
A11: I7 | B11: GrossProfit | C11: 2023-12-31 | D11: USD | E11: 400000000 | F11: available | H11: us-gaap:GrossProfit | I11: GrossProfit | J11: 0000000001-23-000001 | K11: 2024-02-01 | L11: https://www.sec.gov/Archives/edgar/data/1/000000000123000001/annual.htm | O11: -3
A12: I8 | B12: GrossProfit | C12: 2024-12-31 | D12: USD | E12: 500000000 | F12: available | H12: us-gaap:GrossProfit | I12: GrossProfit | J12: 0000000001-24-000001 | K12: 2025-02-01 | L12: https://www.sec.gov/Archives/edgar/data/1/000000000124000001/annual.htm | O12: -3
A13: I9 | B13: OperatingIncomeLoss | C13: 2021-12-31 | D13: USD | E13: 80000000 | F13: available | H13: us-gaap:OperatingIncomeLoss | I13: OperatingIncomeLoss | J13: 0000000001-21-000001 | K13: 2022-02-01 | L13: https://www.sec.gov/Archives/edgar/data/1/000000000121000001/annual.htm | O13: -3
A14: I10 | B14: OperatingIncomeLoss | C14: 2022-12-31 | D14: USD | E14: 90000000 | F14: available | H14: us-gaap:OperatingIncomeLoss | I14: OperatingIncomeLoss | J14: 0000000001-22-000001 | K14: 2023-02-01 | L14: https://www.sec.gov/Archives/edgar/data/1/000000000122000001/annual.htm | O14: -3
A15: I11 | B15: OperatingIncomeLoss | C15: 2023-12-31 | D15: USD | E15: 100000000 | F15: available | H15: us-gaap:OperatingIncomeLoss | I15: OperatingIncomeLoss | J15: 0000000001-23-000001 | K15: 2024-02-01 | L15: https://www.sec.gov/Archives/edgar/data/1/000000000123000001/annual.htm | O15: -3
A16: I12 | B16: OperatingIncomeLoss | C16: 2024-12-31 | D16: USD | E16: 180000000 | F16: available | H16: us-gaap:OperatingIncomeLoss | I16: OperatingIncomeLoss | J16: 0000000001-24-000001 | K16: 2025-02-01 | L16: https://www.sec.gov/Archives/edgar/data/1/000000000124000001/annual.htm | O16: -3
A17: I13 | B17: Retail revenue · Business Segments: Retail | C17: 2021-12-31 | D17: USD | F17: unavailable | G17: No unambiguous annual disclosure.
A18: I14 | B18: Retail revenue · Business Segments: Retail | C18: 2022-12-31 | D18: USD | F18: unavailable | G18: No unambiguous annual disclosure.
A19: I15 | B19: Retail revenue | C19: 2023-12-31 | D19: USD | E19: 400000000 | F19: available | H19: us-gaap:Revenues | I19: Retail revenue | J19: 0000000001-24-000001 | K19: 2025-02-01 | L19: https://www.sec.gov/Archives/edgar/data/1/000000000124000001/annual.htm | M19: retail2023 | N19: demo:BusinessSegmentsAxis=demo:RetailMember | O19: -3
A20: I16 | B20: Retail revenue | C20: 2024-12-31 | D20: USD | E20: 600000000 | F20: available | H20: us-gaap:Revenues | I20: Retail revenue | J20: 0000000001-24-000001 | K20: 2025-02-01 | L20: https://www.sec.gov/Archives/edgar/data/1/000000000124000001/annual.htm | M20: retail2024 | N20: demo:BusinessSegmentsAxis=demo:RetailMember | O20: -3
A21: I17 | B21: AssetsCurrent | C21: 2021-12-31 | D21: USD | E21: 250000000 | F21: available | H21: us-gaap:AssetsCurrent | I21: AssetsCurrent | J21: 0000000001-21-000001 | K21: 2022-02-01 | L21: https://www.sec.gov/Archives/edgar/data/1/000000000121000001/annual.htm | O21: -3
A22: I18 | B22: AssetsCurrent | C22: 2022-12-31 | D22: USD | E22: 300000000 | F22: available | H22: us-gaap:AssetsCurrent | I22: AssetsCurrent | J22: 0000000001-22-000001 | K22: 2023-02-01 | L22: https://www.sec.gov/Archives/edgar/data/1/000000000122000001/annual.htm | O22: -3
A23: I19 | B23: AssetsCurrent | C23: 2023-12-31 | D23: USD | E23: 350000000 | F23: available | H23: us-gaap:AssetsCurrent | I23: AssetsCurrent | J23: 0000000001-23-000001 | K23: 2024-02-01 | L23: https://www.sec.gov/Archives/edgar/data/1/000000000123000001/annual.htm | O23: -3
A24: I20 | B24: AssetsCurrent | C24: 2024-12-31 | D24: USD | E24: 400000000 | F24: available | H24: us-gaap:AssetsCurrent | I24: AssetsCurrent | J24: 0000000001-24-000001 | K24: 2025-02-01 | L24: https://www.sec.gov/Archives/edgar/data/1/000000000124000001/annual.htm | O24: -3
A25: I21 | B25: LiabilitiesCurrent | C25: 2021-12-31 | D25: USD | E25: 100000000 | F25: available | H25: us-gaap:LiabilitiesCurrent | I25: LiabilitiesCurrent | J25: 0000000001-21-000001 | K25: 2022-02-01 | L25: https://www.sec.gov/Archives/edgar/data/1/000000000121000001/annual.htm | O25: -3
A26: I22 | B26: LiabilitiesCurrent | C26: 2022-12-31 | D26: USD | E26: 120000000 | F26: available | H26: us-gaap:LiabilitiesCurrent | I26: LiabilitiesCurrent | J26: 0000000001-22-000001 | K26: 2023-02-01 | L26: https://www.sec.gov/Archives/edgar/data/1/000000000122000001/annual.htm | O26: -3
A27: I23 | B27: LiabilitiesCurrent | C27: 2023-12-31 | D27: USD | E27: 140000000 | F27: available | H27: us-gaap:LiabilitiesCurrent | I27: LiabilitiesCurrent | J27: 0000000001-23-000001 | K27: 2024-02-01 | L27: https://www.sec.gov/Archives/edgar/data/1/000000000123000001/annual.htm | O27: -3
A28: I24 | B28: LiabilitiesCurrent | C28: 2024-12-31 | D28: USD | E28: 160000000 | F28: available | H28: us-gaap:LiabilitiesCurrent | I28: LiabilitiesCurrent | J28: 0000000001-24-000001 | K28: 2025-02-01 | L28: https://www.sec.gov/Archives/edgar/data/1/000000000124000001/annual.htm | O28: -3
A29: I25 | B29: AccountsReceivableNetCurrent | C29: 2021-12-31 | D29: USD | E29: 70000000 | F29: available | H29: us-gaap:AccountsReceivableNetCurrent | I29: AccountsReceivableNetCurrent | J29: 0000000001-21-000001 | K29: 2022-02-01 | L29: https://www.sec.gov/Archives/edgar/data/1/000000000121000001/annual.htm | O29: -3
A30: I26 | B30: AccountsReceivableNetCurrent | C30: 2022-12-31 | D30: USD | E30: 80000000 | F30: available | H30: us-gaap:AccountsReceivableNetCurrent | I30: AccountsReceivableNetCurrent | J30: 0000000001-22-000001 | K30: 2023-02-01 | L30: https://www.sec.gov/Archives/edgar/data/1/000000000122000001/annual.htm | O30: -3
A31: I27 | B31: AccountsReceivableNetCurrent | C31: 2023-12-31 | D31: USD | E31: 90000000 | F31: available | H31: us-gaap:AccountsReceivableNetCurrent | I31: AccountsReceivableNetCurrent | J31: 0000000001-23-000001 | K31: 2024-02-01 | L31: https://www.sec.gov/Archives/edgar/data/1/000000000123000001/annual.htm | O31: -3
A32: I28 | B32: AccountsReceivableNetCurrent | C32: 2024-12-31 | D32: USD | E32: 110000000 | F32: available | H32: us-gaap:AccountsReceivableNetCurrent | I32: AccountsReceivableNetCurrent | J32: 0000000001-24-000001 | K32: 2025-02-01 | L32: https://www.sec.gov/Archives/edgar/data/1/000000000124000001/annual.htm | O32: -3
... A157: I153 | B157: IncomeLossFromContinuingOperationsBeforeIncomeTaxesExtraordinaryItemsNoncontrollingInterest | C157: 2021-12-31 | D157: USD | E157: 75000000 | F157: available | H157: us-gaap:IncomeLossFromContinuingOperationsBeforeIncomeTaxesExtraordinaryItemsNoncontrollingInterest | I157: IncomeLossFromContinuingOperationsBeforeIncomeTaxesExtraordinaryItemsNoncontrollingInterest | J157: 0000000001-21-000001 | K157: 2022-02-01 | L157: https://www.sec.gov/Archives/edgar/data/1/000000000121000001/annual.htm | O157: -3
A158: I154 | B158: NI plus tax less pretax reconciliation | C158: 2021-12-31 | D158: USD | E158: =E153+E154-E157 -> 0 | F158: available
A159: I155 | B159: EBITDA — reconciled historical definition | C159: 2021-12-31 | D159: USD | E159: =E153+E154+E155+E156+0*E158 -> 105000000 | F159: available
A160: I156 | B160: ProfitLoss | C160: 2022-12-31 | D160: USD | E160: 70000000 | F160: available | H160: us-gaap:ProfitLoss | I160: ProfitLoss | J160: 0000000001-22-000001 | K160: 2023-02-01 | L160: https://www.sec.gov/Archives/edgar/data/1/000000000122000001/annual.htm | O160: -3
A161: I157 | B161: IncomeTaxExpenseBenefit | C161: 2022-12-31 | D161: USD | E161: 17500000 | F161: available | H161: us-gaap:IncomeTaxExpenseBenefit | I161: IncomeTaxExpenseBenefit | J161: 0000000001-22-000001 | K161: 2023-02-01 | L161: https://www.sec.gov/Archives/edgar/data/1/000000000122000001/annual.htm | O161: -3
A162: I158 | B162: InterestExpense | C162: 2022-12-31 | D162: USD | E162: 10000000 | F162: available | H162: us-gaap:InterestExpense | I162: InterestExpense | J162: 0000000001-22-000001 | K162: 2023-02-01 | L162: https://www.sec.gov/Archives/edgar/data/1/000000000122000001/annual.htm | O162: -3
A163: I159 | B163: DepreciationDepletionAndAmortization | C163: 2022-12-31 | D163: USD | E163: 22000000 | F163: available | H163: us-gaap:DepreciationDepletionAndAmortization | I163: DepreciationDepletionAndAmortization | J163: 0000000001-22-000001 | K163: 2023-02-01 | L163: https://www.sec.gov/Archives/edgar/data/1/000000000122000001/annual.htm | O163: -3
A164: I160 | B164: IncomeLossFromContinuingOperationsBeforeIncomeTaxesExtraordinaryItemsNoncontrollingInterest | C164: 2022-12-31 | D164: USD | E164: 87500000 | F164: available | H164: us-gaap:IncomeLossFromContinuingOperationsBeforeIncomeTaxesExtraordinaryItemsNoncontrollingInterest | I164: IncomeLossFromContinuingOperationsBeforeIncomeTaxesExtraordinaryItemsNoncontrollingInterest | J164: 0000000001-22-000001 | K164: 2023-02-01 | L164: https://www.sec.gov/Archives/edgar/data/1/000000000122000001/annual.htm | O164: -3
A165: I161 | B165: NI plus tax less pretax reconciliation | C165: 2022-12-31 | D165: USD | E165: =E160+E161-E164 -> 0 | F165: available
...

Sheet Revenue & Segments
A1: Historical teaching fixture | Revenue & Segments
A2: Historical only · currency in millions · missing cells carry explanations
A4: Metric / reported line | B4: 2021-12-31 | C4: 2022-12-31 | D4: 2023-12-31 | E4: 2024-12-31
A5: Revenue & Segments
A6: Revenues [USD million] | B6: ='Calculation Inputs'!E5/1000000 -> 800 | C6: ='Calculation Inputs'!E6/1000000 -> 900 | D6: ='Calculation Inputs'!E7/1000000 -> 1000 | E6: ='Calculation Inputs'!E8/1000000 -> 1200
A7: GrossProfit [USD million] | B7: ='Calculation Inputs'!E9/1000000 -> 300 | C7: ='Calculation Inputs'!E10/1000000 -> 350 | D7: ='Calculation Inputs'!E11/1000000 -> 400 | E7: ='Calculation Inputs'!E12/1000000 -> 500
A8: OperatingIncomeLoss [USD million] | B8: ='Calculation Inputs'!E13/1000000 -> 80 | C8: ='Calculation Inputs'!E14/1000000 -> 90 | D8: ='Calculation Inputs'!E15/1000000 -> 100 | E8: ='Calculation Inputs'!E16/1000000 -> 180
A9: Retail revenue · Business Segments: Retail [USD million] | D9: ='Calculation Inputs'!E19/1000000 -> 400 | E9: ='Calculation Inputs'!E20/1000000 -> 600

Sheet Working Capital
A1: Historical teaching fixture | Working Capital
A2: Historical only · currency in millions · missing cells carry explanations
A4: Metric / reported line | B4: 2021-12-31 | C4: 2022-12-31 | D4: 2023-12-31 | E4: 2024-12-31
A5: Working Capital
A6: AssetsCurrent [USD million] | B6: ='Calculation Inputs'!E21/1000000 -> 250 | C6: ='Calculation Inputs'!E22/1000000 -> 300 | D6: ='Calculation Inputs'!E23/1000000 -> 350 | E6: ='Calculation Inputs'!E24/1000000 -> 400
A7: LiabilitiesCurrent [USD million] | B7: ='Calculation Inputs'!E25/1000000 -> 100 | C7: ='Calculation Inputs'!E26/1000000 -> 120 | D7: ='Calculation Inputs'!E27/1000000 -> 140 | E7: ='Calculation Inputs'!E28/1000000 -> 160
A8: AccountsReceivableNetCurrent [USD million] | B8: ='Calculation Inputs'!E29/1000000 -> 70 | C8: ='Calculation Inputs'!E30/1000000 -> 80 | D8: ='Calculation Inputs'!E31/1000000 -> 90 | E8: ='Calculation Inputs'!E32/1000000 -> 110
A9: InventoryNet [USD million] | B9: ='Calculation Inputs'!E33/1000000 -> 100 | C9: ='Calculation Inputs'!E34/1000000 -> 110 | D9: ='Calculation Inputs'!E35/1000000 -> 120 | E9: ='Calculation Inputs'!E36/1000000 -> 160
A10: AccountsPayableCurrent [USD million] | B10: ='Calculation Inputs'!E37/1000000 -> 50 | C10: ='Calculation Inputs'!E38/1000000 -> 60 | D10: ='Calculation Inputs'!E39/1000000 -> 70 | E10: ='Calculation Inputs'!E40/1000000 -> 90

Sheet Debt & Liquidity
A1: Historical teaching fixture | Debt & Liquidity
A2: Historical only · currency in millions · missing cells carry explanations
A4: Metric / reported line | B4: 2021-12-31 | C4: 2022-12-31 | D4: 2023-12-31 | E4: 2024-12-31
A5: Debt & Liquidity
A6: InterestExpense [USD million] | B6: ='Calculation Inputs'!E41/1000000 -> 10 | C6: ='Calculation Inputs'!E42/1000000 -> 10 | D6: ='Calculation Inputs'!E43/1000000 -> 10 | E6: ='Calculation Inputs'!E44/1000000 -> 12
A7: CashAndCashEquivalentsAtCarryingValue [USD million] | B7: ='Calculation Inputs'!E45/1000000 -> 40 | C7: ='Calculation Inputs'!E46/1000000 -> 45 | D7: ='Calculation Inputs'!E47/1000000 -> 50 | E7: ='Calculation Inputs'!E48/1000000 -> 60
A8: ShortTermInvestments [USD million] | B8: ='Calculation Inputs'!E49/1000000 -> 10 | C8: ='Calculation Inputs'!E50/1000000 -> 12 | D8: ='Calculation Inputs'!E51/1000000 -> 15 | E8: ='Calculation Inputs'!E52/1000000 -> 20
A9: DebtAndCapitalLeaseObligations [USD million] | B9: ='Calculation Inputs'!E53/1000000 -> 100 | C9: ='Calculation Inputs'!E54/1000000 -> 120 | D9: ='Calculation Inputs'!E55/1000000 -> 150 | E9: ='Calculation Inputs'!E56/1000000 -> 180

Sheet Capital & PP&E
A1: Historical teaching fixture | Capital & PP&E
A2: Historical only · currency in millions · missing cells carry explanations
A4: Metric / reported line | B4: 2021-12-31 | C4: 2022-12-31 | D4: 2023-12-31 | E4: 2024-12-31
A5: Capital & PP&E
A6: PaymentsToAcquirePropertyPlantAndEquipment [USD million] | B6: ='Calculation Inputs'!E57/1000000 -> 30 | C6: ='Calculation Inputs'!E58/1000000 -> 40 | D6: ='Calculation Inputs'!E59/1000000 -> 45 | E6: ='Calculation Inputs'!E60/1000000 -> 50
A7: DepreciationDepletionAndAmortization [USD million] | B7: ='Calculation Inputs'!E61/1000000 -> 20 | C7: ='Calculation Inputs'!E62/1000000 -> 22 | D7: ='Calculation Inputs'!E63/1000000 -> 25 | E7: ='Calculation Inputs'!E64/1000000 -> 30

Sheet Earnings & Cash
A1: Historical teaching fixture | Earnings & Cash
A2: Historical only · currency in millions · missing cells carry explanations
A4: Metric / reported line | B4: 2021-12-31 | C4: 2022-12-31 | D4: 2023-12-31 | E4: 2024-12-31
A5: Earnings & Cash
A6: ProfitLoss [USD million] | B6: ='Calculation Inputs'!E65/1000000 -> 60 | C6: ='Calculation Inputs'!E66/1000000 -> 70 | D6: ='Calculation Inputs'!E67/1000000 -> 80 | E6: ='Calculation Inputs'!E68/1000000 -> 120
A7: NetIncomeLoss [USD million] | B7: ='Calculation Inputs'!E69/1000000 -> 58 | C7: ='Calculation Inputs'!E70/1000000 -> 68 | D7: ='Calculation Inputs'!E71/1000000 -> 78 | E7: ='Calculation Inputs'!E72/1000000 -> 118
A8: NetCashProvidedByUsedInOperatingActivities [USD million] | B8: ='Calculation Inputs'!E73/1000000 -> 90 | C8: ='Calculation Inputs'!E74/1000000 -> 100 | D8: ='Calculation Inputs'!E75/1000000 -> 110 | E8: ='Calculation Inputs'!E76/1000000 -> 150
A9: PaymentsToAcquirePropertyPlantAndEquipment [USD million] | B9: ='Calculation Inputs'!E77/1000000 -> 30 | C9: ='Calculation Inputs'!E78/1000000 -> 40 | D9: ='Calculation Inputs'!E79/1000000 -> 45 | E9: ='Calculation Inputs'!E80/1000000 -> 50
A10: DepreciationDepletionAndAmortization [USD million] | B10: ='Calculation Inputs'!E81/1000000 -> 20 | C10: ='Calculation Inputs'!E82/1000000 -> 22 | D10: ='Calculation Inputs'!E83/1000000 -> 25 | E10: ='Calculation Inputs'!E84/1000000 -> 30

Sheet Equity & Shares
A1: Historical teaching fixture | Equity & Shares
A2: Historical only · currency in millions · missing cells carry explanations
A4: Metric / reported line | B4: 2021-12-31 | C4: 2022-12-31 | D4: 2023-12-31 | E4: 2024-12-31
A5: Equity & Shares
A6: NetIncomeLossAvailableToCommonStockholdersBasic [USD million] | B6: ='Calculation Inputs'!E85/1000000 -> 58 | C6: ='Calculation Inputs'!E86/1000000 -> 68 | D6: ='Calculation Inputs'!E87/1000000 -> 78 | E6: ='Calculation Inputs'!E88/1000000 -> 118
A7: CommonStockDividendsPerShareDeclared [USD/shares] | B7: ='Calculation Inputs'!E89 -> 0.1 | C7: ='Calculation Inputs'!E90 -> 0.12 | D7: ='Calculation Inputs'!E91 -> 0.15 | E7: ='Calculation Inputs'!E92 -> 0.25
A8: EarningsPerShareBasic [USD/shares] | B8: ='Calculation Inputs'!E93 -> 0.58 | C8: ='Calculation Inputs'!E94 -> 0.68 | D8: ='Calculation Inputs'!E95 -> 0.78 | E8: ='Calculation Inputs'!E96 -> 1.475
A9: EarningsPerShareDiluted [USD/shares] | B9: ='Calculation Inputs'!E97 -> 0.58 | C9: ='Calculation Inputs'!E98 -> 0.68 | D9: ='Calculation Inputs'!E99 -> 0.78 | E9: ='Calculation Inputs'!E100 -> 1.475
A10: WeightedAverageNumberOfDilutedSharesOutstanding [shares] | B10: ='Calculation Inputs'!E101 -> 100000000 | C10: ='Calculation Inputs'!E102 -> 100000000 | D10: ='Calculation Inputs'!E103 -> 100000000 | E10: ='Calculation Inputs'!E104 -> 80000000
A11: CommonStockholdersEquity [USD million] | B11: ='Calculation Inputs'!E105/1000000 -> 400 | C11: ='Calculation Inputs'!E106/1000000 -> 450 | D11: ='Calculation Inputs'!E107/1000000 -> 500 | E11: ='Calculation Inputs'!E108/1000000 -> 600
A12: StockholdersEquityIncludingPortionAttributableToNoncontrollingInterest [USD million] | B12: ='Calculation Inputs'!E109/1000000 -> 410 | C12: ='Calculation Inputs'!E110/1000000 -> 460 | D12: ='Calculation Inputs'!E111/1000000 -> 510 | E12: ='Calculation Inputs'!E112/1000000 -> 620
A13: PaymentsOfDividendsCommonStock [USD million] | B13: ='Calculation Inputs'!E113/1000000 -> 10 | C13: ='Calculation Inputs'!E114/1000000 -> 12 | D13: ='Calculation Inputs'!E115/1000000 -> 15 | E13: ='Calculation Inputs'!E116/1000000 -> 20
A14: PaymentsForRepurchaseOfCommonStock [USD million] | B14: ='Calculation Inputs'!E117/1000000 -> 20 | C14: ='Calculation Inputs'!E118/1000000 -> 25 | D14: ='Calculation Inputs'!E119/1000000 -> 30 | E14: ='Calculation Inputs'!E120/1000000 -> 40

Sheet EBITDA & Capital
A1: Historical teaching fixture | EBITDA & Capital
A2: Historical only · currency in millions · missing cells carry explanations
A4: Metric / reported line | B4: 2021-12-31 | C4: 2022-12-31 | D4: 2023-12-31 | E4: 2024-12-31
A5: EBITDA & Capital
A6: ProfitLoss [USD million] | B6: ='Calculation Inputs'!E121/1000000 -> 60 | C6: ='Calculation Inputs'!E122/1000000 -> 70 | D6: ='Calculation Inputs'!E123/1000000 -> 80 | E6: ='Calculation Inputs'!E124/1000000 -> 120
A7: InterestExpense [USD million] | B7: ='Calculation Inputs'!E125/1000000 -> 10 | C7: ='Calculation Inputs'!E126/1000000 -> 10 | D7: ='Calculation Inputs'!E127/1000000 -> 10 | E7: ='Calculation Inputs'!E128/1000000 -> 12
A8: IncomeLossFromContinuingOperationsBeforeIncomeTaxesExtraordinaryItemsNoncontrollingInterest [USD million] | B8: ='Calculation Inputs'!E129/1000000 -> 75 | C8: ='Calculation Inputs'!E130/1000000 -> 87.5 | D8: ='Calculation Inputs'!E131/1000000 -> 100 | E8: ='Calculation Inputs'!E132/1000000 -> 150
A9: IncomeTaxExpenseBenefit [USD million] | B9: ='Calculation Inputs'!E133/1000000 -> 15 | C9: ='Calculation Inputs'!E134/1000000 -> 17.5 | D9: ='Calculation Inputs'!E135/1000000 -> 20 | E9: ='Calculation Inputs'!E136/1000000 -> 30
A10: CashAndCashEquivalentsAtCarryingValue [USD million] | B10: ='Calculation Inputs'!E137/1000000 -> 40 | C10: ='Calculation Inputs'!E138/1000000 -> 45 | D10: ='Calculation Inputs'!E139/1000000 -> 50 | E10: ='Calculation Inputs'!E140/1000000 -> 60
A11: DebtAndCapitalLeaseObligations [USD million] | B11: ='Calculation Inputs'!E141/1000000 -> 100 | C11: ='Calculation Inputs'!E142/1000000 -> 120 | D11: ='Calculation Inputs'!E143/1000000 -> 150 | E11: ='Calculation Inputs'!E144/1000000 -> 180
A12: StockholdersEquityIncludingPortionAttributableToNoncontrollingInterest [USD million] | B12: ='Calculation Inputs'!E145/1000000 -> 410 | C12: ='Calculation Inputs'!E146/1000000 -> 460 | D12: ='Calculation Inputs'!E147/1000000 -> 510 | E12: ='Calculation Inputs'!E148/1000000 -> 620
A13: DepreciationDepletionAndAmortization [USD million] | B13: ='Calculation Inputs'!E149/1000000 -> 20 | C13: ='Calculation Inputs'!E150/1000000 -> 22 | D13: ='Calculation Inputs'!E151/1000000 -> 25 | E13: ='Calculation Inputs'!E152/1000000 -> 30
A14: Earnings bridge
A15: EBITDA — reconciled historical definition [reported currency million] | B15: ='Calculation Inputs'!E159/1000000 -> 105 | C15: ='Calculation Inputs'!E166/1000000 -> 119.5 | D15: ='Calculation Inputs'!E173/1000000 -> 135 | E15: ='Calculation Inputs'!E180/1000000 -> 192
A16: EBITDA margin — reconciled definition [%] | B16: ='Calculation Inputs'!E182 -> 0.13125 | C16: ='Calculation Inputs'!E184 -> 0.13277778 | D16: ='Calculation Inputs'!E186 -> 0.135 | E16: ='Calculation Inputs'!E188 -> 0.16
A17: Capital efficiency
A18: Consolidated equity / assets [%] | B18: ='Calculation Inputs'!E191 -> 0.5125 | C18: ='Calculation Inputs'!E194 -> 0.51111111 | D18: ='Calculation Inputs'!E197 -> 0.46363636 | E18: ='Calculation Inputs'!E200 -> 0.47692308
A19: Effective tax rate — reconciled [%] | B19: ='Calculation Inputs'!E201 -> 0.2 | C19: ='Calculation Inputs'!E202 -> 0.2 | D19: ='Calculation Inputs'!E203 -> 0.2 | E19: ='Calculation Inputs'!E204 -> 0.2
A20: After-tax operating income — ETR proxy [reported currency million] | B20: ='Calculation Inputs'!E206/1000000 -> 64 | C20: ='Calculation Inputs'!E208/1000000 -> 72 | D20: ='Calculation Inputs'!E210/1000000 -> 80 | E20: ='Calculation Inputs'!E212/1000000 -> 144
A21: Invested capital — cash-deducted proxy [reported currency million] | B21: ='Calculation Inputs'!E215/1000000 -> 470 | C21: ='Calculation Inputs'!E218/1000000 -> 535 | D21: ='Calculation Inputs'!E221/1000000 -> 610 | E21: ='Calculation Inputs'!E224/1000000 -> 740
A22: ROIC — effective-tax, cash-deducted proxy [%] | C22: ='Calculation Inputs'!E227 -> 0.14328358 | D22: ='Calculation Inputs'!E229 -> 0.13973799 | E22: ='Calculation Inputs'!E231 -> 0.21333333

Sheet Operating KPIs
A1: Historical teaching fixture | Operating KPIs
A2: Historical only · currency in millions · missing cells carry explanations
A4: Metric / reported line | B4: 2021-12-31 | C4: 2022-12-31 | D4: 2023-12-31 | E4: 2024-12-31
A5: Operating KPIs
A6: Active accounts · note disclosure [pure] | D6: ='Calculation Inputs'!E234 -> 10 | E6: ='Calculation Inputs'!E235 -> 12

Sheet Historical Ratios
A1: Historical teaching fixture | Historical Ratios
A2: Historical only · currency in millions · missing cells carry explanations
A4: Metric / reported line | B4: 2021-12-31 | C4: 2022-12-31 | D4: 2023-12-31 | E4: 2024-12-31
A5: Growth
A6: Revenue growth [%] | C6: ='Calculation Inputs'!E237 -> 0.125 | D6: ='Calculation Inputs'!E238 -> 0.11111111 | E6: ='Calculation Inputs'!E239 -> 0.2
A7: Revenue CAGR — 3 annual intervals [%] | E7: ='Calculation Inputs'!E243 -> 0.14471424
A8: Profitability
A9: Gross margin [%] | B9: ='Calculation Inputs'!E245 -> 0.375 | C9: ='Calculation Inputs'!E247 -> 0.38888889 | D9: ='Calculation Inputs'!E249 -> 0.4 | E9: ='Calculation Inputs'!E251 -> 0.41666667
A10: Operating margin [%] | B10: ='Calculation Inputs'!E252 -> 0.1 | C10: ='Calculation Inputs'!E253 -> 0.1 | D10: ='Calculation Inputs'!E254 -> 0.1 | E10: ='Calculation Inputs'!E255 -> 0.15
A11: Parent net margin [%] | B11: ='Calculation Inputs'!E257 -> 0.0725 | C11: ='Calculation Inputs'!E259 -> 0.075555556 | D11: ='Calculation Inputs'!E261 -> 0.078 | E11: ='Calculation Inputs'!E263 -> 0.098333333
A12: SG&A / revenue [%]
A13: R&D / revenue [%]
A14: Capital investment
A15: PP&E purchases / revenue [%] | B15: ='Calculation Inputs'!E281 -> 0.0375 | C15: ='Calculation Inputs'!E283 -> 0.044444444 | D15: ='Calculation Inputs'!E285 -> 0.045 | E15: ='Calculation Inputs'!E287 -> 0.041666667
A16: Returns
A17: Return on assets — consolidated [%] | C17: ='Calculation Inputs'!E291 -> 0.082352941 | D17: ='Calculation Inputs'!E293 -> 0.08 | E17: ='Calculation Inputs'!E295 -> 0.1
A18: Return on common equity [%] | C18: ='Calculation Inputs'!E303 -> 0.16 | D18: ='Calculation Inputs'!E307 -> 0.16421053 | E18: ='Calculation Inputs'!E311 -> 0.21454545
A19: Liquidity
A20: Current ratio [x] | B20: ='Calculation Inputs'!E314 -> 2.5 | C20: ='Calculation Inputs'!E317 -> 2.5 | D20: ='Calculation Inputs'!E320 -> 2.5 | E20: ='Calculation Inputs'!E323 -> 2.5
A21: Quick ratio — strict components [x] | B21: ='Calculation Inputs'!E326 -> 1.2 | C21: ='Calculation Inputs'!E329 -> 1.1416667 | D21: ='Calculation Inputs'!E332 -> 1.1071429 | E21: ='Calculation Inputs'!E335 -> 1.1875
A22: Debt
A23: Reported debt incl. finance leases less cash [reported currency million] | B23: ='Calculation Inputs'!E336/1000000 -> 60 | C23: ='Calculation Inputs'!E337/1000000 -> 75 | D23: ='Calculation Inputs'!E338/1000000 -> 100 | E23: ='Calculation Inputs'!E339/1000000 -> 120
A24: Reported debt incl. finance leases / assets [%] | B24: ='Calculation Inputs'!E340 -> 0.125 | C24: ='Calculation Inputs'!E341 -> 0.13333333 | D24: ='Calculation Inputs'!E342 -> 0.13636364 | E24: ='Calculation Inputs'!E343 -> 0.13846154
A25: Operating income / interest expense [x] | B25: ='Calculation Inputs'!E344 -> 8 | C25: ='Calculation Inputs'!E345 -> 9 | D25: ='Calculation Inputs'!E346 -> 10 | E25: ='Calculation Inputs'!E347 -> 15
A26: Working capital
A27: Receivable days — sales proxy [days] | C27: ='Calculation Inputs'!E353 -> 30.416667 | D27: ='Calculation Inputs'!E356 -> 31.025 | E27: ='Calculation Inputs'!E359 -> 30.5
A28: Inventory days [days] | C28: ='Calculation Inputs'!E369 -> 69.681818 | D28: ='Calculation Inputs'!E374 -> 69.958333 | E28: ='Calculation Inputs'!E379 -> 73.2
A29: Payable days — cost-of-sales proxy [days] | C29: ='Calculation Inputs'!E387 -> 36.5 | D29: ='Calculation Inputs'!E391 -> 39.541667 | E29: ='Calculation Inputs'!E395 -> 41.828571
A30: Cash conversion cycle — proxy [days] | C30: ='Calculation Inputs'!E397 -> 63.598485 | D30: ='Calculation Inputs'!E398 -> 61.441667 | E30: ='Calculation Inputs'!E399 -> 61.871429
A31: Cash generation
A32: Operating cash flow / revenue [%] | B32: ='Calculation Inputs'!E401 -> 0.1125 | C32: ='Calculation Inputs'!E403 -> 0.11111111 | D32: ='Calculation Inputs'!E405 -> 0.11 | E32: ='Calculation Inputs'!E407 -> 0.125
A33: Operating cash flow / earnings [x] | B33: ='Calculation Inputs'!E408 -> 1.5 | C33: ='Calculation Inputs'!E409 -> 1.4285714 | D33: ='Calculation Inputs'!E410 -> 1.375 | E33: ='Calculation Inputs'!E411 -> 1.25
A34: Operating cash flow less PP&E purchases [reported currency million] | B34: ='Calculation Inputs'!E412/1000000 -> 60 | C34: ='Calculation Inputs'!E413/1000000 -> 60 | D34: ='Calculation Inputs'!E414/1000000 -> 65 | E34: ='Calculation Inputs'!E415/1000000 -> 100
A35: Earnings and cash
A36: Earnings less operating cash flow [reported currency million] | B36: ='Calculation Inputs'!E416/1000000 -> -30 | C36: ='Calculation Inputs'!E417/1000000 -> -30 | D36: ='Calculation Inputs'!E418/1000000 -> -30 | E36: ='Calculation Inputs'!E419/1000000 -> -30
A37: Earnings–cash difference / average assets [%] | C37: ='Calculation Inputs'!E423 -> -0.035294118 | D37: ='Calculation Inputs'!E425 -> -0.03 | E37: ='Calculation Inputs'!E427 -> -0.025
A38: Earnings bridge
A39: EBITDA — reconciled historical definition [reported currency million] | B39: ='Calculation Inputs'!E159/1000000 -> 105 | C39: ='Calculation Inputs'!E166/1000000 -> 119.5 | D39: ='Calculation Inputs'!E173/1000000 -> 135 | E39: ='Calculation Inputs'!E180/1000000 -> 192
A40: EBITDA margin — reconciled definition [%] | B40: ='Calculation Inputs'!E182 -> 0.13125 | C40: ='Calculation Inputs'!E184 -> 0.13277778 | D40: ='Calculation Inputs'!E186 -> 0.135 | E40: ='Calculation Inputs'!E188 -> 0.16
A41: Debt
...

Sheet Return Bridge
A1: Historical teaching fixture | Return Bridge
A2: Historical only · currency in millions · missing cells carry explanations
A4: Metric / reported line | B4: 2021-12-31 | C4: 2022-12-31 | D4: 2023-12-31 | E4: 2024-12-31
A5: Return bridge
A6: Asset turnover — total assets [x] | C6: ='Calculation Inputs'!E548 -> 1.0588235 | D6: ='Calculation Inputs'!E550 -> 1 | E6: ='Calculation Inputs'!E552 -> 1
A7: Operating return on total assets [%] | C7: ='Calculation Inputs'!E556 -> 0.10588235 | D7: ='Calculation Inputs'!E558 -> 0.1 | E7: ='Calculation Inputs'!E560 -> 0.15
A8: Change in operating return [pp] | D8: ='Calculation Inputs'!E563*100 -> -0.58823529 | E8: ='Calculation Inputs'!E564*100 -> 5
A9: Margin-change contribution [pp] | D9: ='Calculation Inputs'!E567*100 -> 0 | E9: ='Calculation Inputs'!E568*100 -> 5
A10: Turnover-change contribution [pp] | D10: ='Calculation Inputs'!E571*100 -> -0.58823529 | E10: ='Calculation Inputs'!E572*100 -> 0
A11: Margin/turnover interaction [pp] | D11: ='Calculation Inputs'!E575*100 -> 0 | E11: ='Calculation Inputs'!E576*100 -> 0

Sheet Common Size
A1: Historical teaching fixture | Common Size
A2: Historical only · currency in millions · missing cells carry explanations
A4: Metric / reported line | B4: 2021-12-31 | C4: 2022-12-31 | D4: 2023-12-31 | E4: 2024-12-31
A5: Profit & Loss
A6: Revenues [%] | B6: ='Calculation Inputs'!E578 -> 1 | C6: ='Calculation Inputs'!E580 -> 1 | D6: ='Calculation Inputs'!E582 -> 1 | E6: ='Calculation Inputs'!E584 -> 1
A7: CostOfRevenue [%] | B7: ='Calculation Inputs'!E586 -> 0.625 | C7: ='Calculation Inputs'!E588 -> 0.61111111 | D7: ='Calculation Inputs'!E590 -> 0.6 | E7: ='Calculation Inputs'!E592 -> 0.58333333
A8: GrossProfit [%] | B8: ='Calculation Inputs'!E594 -> 0.375 | C8: ='Calculation Inputs'!E596 -> 0.38888889 | D8: ='Calculation Inputs'!E598 -> 0.4 | E8: ='Calculation Inputs'!E600 -> 0.41666667
A9: OperatingIncomeLoss [%] | B9: ='Calculation Inputs'!E602 -> 0.1 | C9: ='Calculation Inputs'!E604 -> 0.1 | D9: ='Calculation Inputs'!E606 -> 0.1 | E9: ='Calculation Inputs'!E608 -> 0.15
A10: ProfitLoss [%] | B10: ='Calculation Inputs'!E610 -> 0.075 | C10: ='Calculation Inputs'!E612 -> 0.077777778 | D10: ='Calculation Inputs'!E614 -> 0.08 | E10: ='Calculation Inputs'!E616 -> 0.1
A11: NetIncomeLoss [%] | B11: ='Calculation Inputs'!E618 -> 0.0725 | C11: ='Calculation Inputs'!E620 -> 0.075555556 | D11: ='Calculation Inputs'!E622 -> 0.078 | E11: ='Calculation Inputs'!E624 -> 0.098333333
A12: NetIncomeLossAvailableToCommonStockholdersBasic [%] | B12: ='Calculation Inputs'!E626 -> 0.0725 | C12: ='Calculation Inputs'!E628 -> 0.075555556 | D12: ='Calculation Inputs'!E630 -> 0.078 | E12: ='Calculation Inputs'!E632 -> 0.098333333
A13: InterestExpense [%] | B13: ='Calculation Inputs'!E634 -> 0.0125 | C13: ='Calculation Inputs'!E636 -> 0.011111111 | D13: ='Calculation Inputs'!E638 -> 0.01 | E13: ='Calculation Inputs'!E640 -> 0.01
A14: IncomeLossFromContinuingOperationsBeforeIncomeTaxesExtraordinaryItemsNoncontrollingInterest [%] | B14: ='Calculation Inputs'!E642 -> 0.09375 | C14: ='Calculation Inputs'!E644 -> 0.097222222 | D14: ='Calculation Inputs'!E646 -> 0.1 | E14: ='Calculation Inputs'!E648 -> 0.125
A15: IncomeTaxExpenseBenefit [%] | B15: ='Calculation Inputs'!E650 -> 0.01875 | C15: ='Calculation Inputs'!E652 -> 0.019444444 | D15: ='Calculation Inputs'!E654 -> 0.02 | E15: ='Calculation Inputs'!E656 -> 0.025
A16: Balance Sheet
A17: Assets [%] | B17: ='Calculation Inputs'!E658 -> 1 | C17: ='Calculation Inputs'!E660 -> 1 | D17: ='Calculation Inputs'!E662 -> 1 | E17: ='Calculation Inputs'!E664 -> 1
A18: LiabilitiesAndStockholdersEquity [%] | B18: ='Calculation Inputs'!E666 -> 1 | C18: ='Calculation Inputs'!E668 -> 1 | D18: ='Calculation Inputs'!E670 -> 1 | E18: ='Calculation Inputs'!E672 -> 1
A19: AssetsCurrent [%] | B19: ='Calculation Inputs'!E674 -> 0.3125 | C19: ='Calculation Inputs'!E676 -> 0.33333333 | D19: ='Calculation Inputs'!E678 -> 0.31818182 | E19: ='Calculation Inputs'!E680 -> 0.30769231
A20: LiabilitiesCurrent [%] | B20: ='Calculation Inputs'!E682 -> 0.125 | C20: ='Calculation Inputs'!E684 -> 0.13333333 | D20: ='Calculation Inputs'!E686 -> 0.12727273 | E20: ='Calculation Inputs'!E688 -> 0.12307692
A21: CashAndCashEquivalentsAtCarryingValue [%] | B21: ='Calculation Inputs'!E690 -> 0.05 | C21: ='Calculation Inputs'!E692 -> 0.05 | D21: ='Calculation Inputs'!E694 -> 0.045454545 | E21: ='Calculation Inputs'!E696 -> 0.046153846
A22: ShortTermInvestments [%] | B22: ='Calculation Inputs'!E698 -> 0.0125 | C22: ='Calculation Inputs'!E700 -> 0.013333333 | D22: ='Calculation Inputs'!E702 -> 0.013636364 | E22: ='Calculation Inputs'!E704 -> 0.015384615
A23: AccountsReceivableNetCurrent [%] | B23: ='Calculation Inputs'!E706 -> 0.0875 | C23: ='Calculation Inputs'!E708 -> 0.088888889 | D23: ='Calculation Inputs'!E710 -> 0.081818182 | E23: ='Calculation Inputs'!E712 -> 0.084615385
A24: InventoryNet [%] | B24: ='Calculation Inputs'!E714 -> 0.125 | C24: ='Calculation Inputs'!E716 -> 0.12222222 | D24: ='Calculation Inputs'!E718 -> 0.10909091 | E24: ='Calculation Inputs'!E720 -> 0.12307692
A25: AccountsPayableCurrent [%] | B25: ='Calculation Inputs'!E722 -> 0.0625 | C25: ='Calculation Inputs'!E724 -> 0.066666667 | D25: ='Calculation Inputs'!E726 -> 0.063636364 | E25: ='Calculation Inputs'!E728 -> 0.069230769
A26: CommonStockholdersEquity [%] | B26: ='Calculation Inputs'!E730 -> 0.5 | C26: ='Calculation Inputs'!E732 -> 0.5 | D26: ='Calculation Inputs'!E734 -> 0.45454545 | E26: ='Calculation Inputs'!E736 -> 0.46153846
A27: DebtAndCapitalLeaseObligations [%] | B27: ='Calculation Inputs'!E738 -> 0.125 | C27: ='Calculation Inputs'!E740 -> 0.13333333 | D27: ='Calculation Inputs'!E742 -> 0.13636364 | E27: ='Calculation Inputs'!E744 -> 0.13846154
A28: StockholdersEquityIncludingPortionAttributableToNoncontrollingInterest [%] | B28: ='Calculation Inputs'!E746 -> 0.5125 | C28: ='Calculation Inputs'!E748 -> 0.51111111 | D28: ='Calculation Inputs'!E750 -> 0.46363636 | E28: ='Calculation Inputs'!E752 -> 0.47692308

Sheet Business Drivers
A1: Historical teaching fixture | Business Drivers
A2: Historical only · currency in millions · missing cells carry explanations
A4: Metric / reported line | B4: 2021-12-31 | C4: 2022-12-31 | D4: 2023-12-31 | E4: 2024-12-31
A5: Business drivers
